Workbook
Name BILLETE: INDICES!$C$4
Name COMI1: INDICES!$C$20
Name COMI2: INDICES!$C$21
Name INFLACION: INDICES!$C$16
Name LOG_SEG: INDICES!$C$24
Name MARGEN: INDICES!$C$3

Sheet Prof&LosT
G1: COMPRA COSTOS ---- COMPRA COSTOS ----- COMPRA COSTOS---- COMPRA COSTOS COMPRA COSTOS ---- COMPRA COSTOS ----- COMPRA COSTOS---- COMPRA COSTOS | V1: PRECIO DE VENTA ----- PRECIO DE VENTA ------ PRECIO DE VENTA----- PRECIO DE VENTA---- PRECIO DE VENTA ------- PRECIO DE VENTA ----- PRECIO DE VENTA ------ PRECIO DE VENTA----- PRECIO DE VENTA---- PRECIO DE VENTA
D2: MANO DE OB RA | G2: UNITARIO COSTO | P2: TOTAL COSTO | V2: VENTA UNITARIO | AD2: VENTA TOTAL
A3: item | B3: UN | C3: CODIGO | D3: DESCRIPCIÓN | E3: PROV | F3: CANT | G3: COSTO INCIAL | H3: LOG Y SEG UNIT | I3: COSTO BASE UNIT + envío USD | J3: AlicIVA | K3: IVA | L3: % IMP INTERNO | M3: IMPUESTOS INTERNOS | N3: COSTO BASE S/IVA | O3: COSTO BASE + IVA UNIT | P3: LOG Y SEG TOTAL | Q3: COSTO BASE TOT S/ IVA | R3: IVA TOTAL | S3: IMP INTERNOS TOTAL | T3: COSTO TOT S/ IVA | U3: COSTO TOT C/ IVA + IMP | V3: NETO UNITARIO | W3: COMISIONES | X3: NETO + COMISIONES UNITARIO | Y3: COSTO FINANCIERO UNITARIO | Z3: UNIT + COSTO FINAN. (UNIT S/IVA) | AA3: IVA unitario | AB3: UNIT C/IVA usd | AC3: UNIT C/IVA pesos | AD3: NETO TOTAL | AE3: COMISIONES TOTAL | AF3: COSTO FINANCIERO TOTAL | AG3: TOTAL SIN IVA CON COSTO FINANCIERO | AH3: IVA TOTAL | AI3: TOTAL C/ IVA | AJ3: TOTAL C/IVA PESOS
A4: 1 | B4: UN | C4: SBD1 | D4: MANO DE OBRA | E4: LEO | F4: 1 | G4: 25000 | H4: =(G4*LOG_SEG) -> 500 | I4: =G4+H4 -> 25500 | J4: 0.21 | K4: =I4*J4 -> 5355 | L4: 0 | M4: =G4*L4 -> 0 | N4: =I4+M4 -> 25500 | O4: =N4+K4 -> 30855 | P4: =H4*F4 -> 500 | Q4: =N4*F4 -> 25500 | R4: =K4*F4 -> 5355 | S4: =M4*F4 -> 0 | T4: =Q4+S4 -> 25500 | U4: =T4+R4 -> 30855 | V4: =ROUND(N4/(1-MARGEN),2) -> 46028.88 | W4: =X4-V4 -> 10103.9 | X4: =ROUND(V4/(1-(COMI1+COMI2)),2) -> 56132.78 | Y4: =Z4-X4 -> 0 | Z4: =ROUND(X4*INFLACION,2) -> 56132.78 | AA4: =ROUND(Z4*J4,2) -> 11787.88 | AB4: =ROUND(Z4+AA4,2) -> 67920.66 | AC4: =ROUND(AB4*BILLETE,2) -> 96786940 | AD4: =V4*F4 -> 46028.88 | AE4: =W4*F4 -> 10103.9 | AF4: =Y4*F4 -> 0 | AG4: =ROUND(Z4*F4,2) -> 56132.78 | AH4: =ROUND(AA4*F4,2) -> 11787.88 | AI4: =AG4+AH4 -> 67920.66 | AJ4: =AI4*BILLETE -> 96786940
A5: 1 | B5: UN | C5: SBD2 | D5: CONFIGURACIÓN RED Y PUESTA A PUNTO | E5: Clickit | F5: 1 | G5: 10000 | H5: =(G5*LOG_SEG) -> 200 | I5: =G5+H5 -> 10200 | J5: 0.21 | K5: =I5*J5 -> 2142 | L5: 0 | M5: =G5*L5 -> 0 | N5: =I5+M5 -> 10200 | O5: =N5+K5 -> 12342 | P5: =H5*F5 -> 200 | Q5: =N5*F5 -> 10200 | R5: =K5*F5 -> 2142 | S5: =M5*F5 -> 0 | T5: =Q5+S5 -> 10200 | U5: =T5+R5 -> 12342 | V5: =ROUND(N5/(1-MARGEN),2) -> 18411.55 | W5: =X5-V5 -> 4041.56 | X5: =ROUND(V5/(1-(COMI1+COMI2)),2) -> 22453.11 | Y5: =Z5-X5 -> 0 | Z5: =ROUND(X5*INFLACION,2) -> 22453.11 | AA5: =ROUND(Z5*J5,2) -> 4715.15 | AB5: =ROUND(Z5+AA5,2) -> 27168.26 | AC5: =ROUND(AB5*BILLETE,2) -> 38714770 | AD5: =V5*F5 -> 18411.55 | AE5: =W5*F5 -> 4041.56 | AF5: =Y5*F5 -> 0 | AG5: =ROUND(Z5*F5,2) -> 22453.11 | AH5: =ROUND(AA5*F5,2) -> 4715.15 | AI5: =AG5+AH5 -> 27168.26 | AJ5: =AI5*BILLETE -> 38714770
T6: =SUM(T4:T5) -> 35700 | U6: =SUM(U4:U5) -> 43197 | AG6: =SUM(AG4:AG5) -> 78585.89 | AH6: =SUM(AH4:AH5) -> 16503.03 | AI6: =SUM(AI4:AI5) -> 95088.92 | AJ6: =SUM(AJ4:AJ5) -> 135501711
G8: COMPRA COSTOS ---- COMPRA COSTOS ----- COMPRA COSTOS---- COMPRA COSTOS COMPRA COSTOS ---- COMPRA COSTOS ----- COMPRA COSTOS---- COMPRA COSTOS | V8: PRECIO DE VENTA ----- PRECIO DE VENTA ------ PRECIO DE VENTA----- PRECIO DE VENTA---- PRECIO DE VENTA ------- PRECIO DE VENTA ----- PRECIO DE VENTA ------ PRECIO DE VENTA----- PRECIO DE VENTA---- PRECIO DE VENTA
D9: EQUIPOS | G9: UNITARIO COSTO | P9: TOTAL COSTO | V9: VENTA UNITARIO | AD9: VENTA TOTAL
A10: item | B10: UN | C10: CODIGO | D10: DESCRIPCIÓN | E10: PROV | F10: CANT | G10: COSTO INCIAL | H10: LOG Y SEG UNIT | I10: COSTO BASE UNIT + envío USD | J10: AlicIVA | K10: IVA | L10: % IMP INTERNO | M10: IMPUESTOS INTERNOS | N10: COSTO BASE S/IVA | O10: COSTO BASE + IVA UNIT | P10: LOG Y SEG TOTAL | Q10: COSTO BASE TOT S/ IVA | R10: IVA TOTAL | S10: IMP INTERNOS TOTAL | T10: COSTO TOT S/ IVA | U10: COSTO TOT C/ IVA + IMP | V10: NETO UNITARIO | W10: COMISIONES | X10: NETO + COMISIONES UNITARIO | Y10: COSTO FINANCIERO UNITARIO | Z10: UNIT + COSTO FINAN. (UNIT S/IVA) | AA10: IVA unitario | AB10: UNIT C/IVA usd | AC10: UNIT C/IVA pesos | AD10: NETO TOTAL | AE10: COMISIONES TOTAL | AF10: COSTO FINANCIERO TOTAL | AG10: TOTAL SIN IVA CON COSTO FINANCIERO | AH10: IVA TOTAL | AI10: TOTAL C/ IVA | AJ10: TOTAL C/IVA PESOS
A11: 1 | B11: UN | C11: USW-PRO-48 | D11: UNIFI SWITCH 48 PORT 10/100/1000 + 4 SFP 10 GB PRO 600W POE | E11: ITEM 7 | F11: 10 | G11: 1109 | H11: =(G11*LOG_SEG) -> 22.18 | I11: =G11+H11 -> 1131.18 | J11: 0.105 | K11: =I11*J11 -> 118.7739 | L11: 0 | M11: =G11*L11 -> 0 | N11: =I11+M11 -> 1131.18 | O11: =N11+K11 -> 1249.9539 | P11: =H11*F11 -> 221.8 | Q11: =N11*F11 -> 11311.8 | R11: =K11*F11 -> 1187.739 | S11: =M11*F11 -> 0 | T11: =Q11+S11 -> 11311.8 | U11: =T11+R11 -> 12499.539 | V11: =ROUND(N11/(1-MARGEN),2) -> 2041.84 | W11: =X11-V11 -> 448.21 | X11: =ROUND(V11/(1-(COMI1+COMI2)),2) -> 2490.05 | Y11: =Z11-X11 -> 0 | Z11: =ROUND(X11*INFLACION,2) -> 2490.05 | AA11: =ROUND(Z11*J11,2) -> 261.46 | AB11: =ROUND(Z11+AA11,2) -> 2751.51 | AC11: =ROUND(AB11*BILLETE,2) -> 3920901.8 | AD11: =V11*F11 -> 20418.4 | AE11: =W11*F11 -> 4482.1 | AF11: =Y11*F11 -> 0 | AG11: =ROUND(Z11*F11,2) -> 24900.5 | AH11: =ROUND(AA11*F11,2) -> 2614.6 | AI11: =AG11+AH11 -> 27515.1 | AJ11: =AI11*BILLETE -> 39209018
A12: 2 | B12: UN | C12: U6-LR | D12: UNIFI AP UBIQUITI WIFI 6 LONGR SIN FUENTE | E12: ITEM 8 | F12: 17 | G12: 160 | H12: =(G12*LOG_SEG) -> 3.2 | I12: =G12+H12 -> 163.2 | J12: 0.105 | K12: =I12*J12 -> 17.136 | L12: 0 | M12: =G12*L12 -> 0 | N12: =I12+M12 -> 163.2 | O12: =N12+K12 -> 180.336 | P12: =H12*F12 -> 54.4 | Q12: =N12*F12 -> 2774.4 | R12: =K12*F12 -> 291.312 | S12: =M12*F12 -> 0 | T12: =Q12+S12 -> 2774.4 | U12: =T12+R12 -> 3065.712 | V12: =ROUND(N12/(1-MARGEN),2) -> 294.58 | W12: =X12-V12 -> 64.66 | X12: =ROUND(V12/(1-(COMI1+COMI2)),2) -> 359.24 | Y12: =Z12-X12 -> 0 | Z12: =ROUND(X12*INFLACION,2) -> 359.24 | AA12: =ROUND(Z12*J12,2) -> 37.72 | AB12: =ROUND(Z12+AA12,2) -> 396.96 | AC12: =ROUND(AB12*BILLETE,2) -> 565668 | AD12: =V12*F12 -> 5007.86 | AE12: =W12*F12 -> 1099.22 | AF12: =Y12*F12 -> 0 | AG12: =ROUND(Z12*F12,2) -> 6107.08 | AH12: =ROUND(AA12*F12,2) -> 641.24 | AI12: =AG12+AH12 -> 6748.32 | AJ12: =AI12*BILLETE -> 9616356
A13: 3 | B13: UN | C13: UCG-FIBER | D13: UNIFI GATEWAY UCG FIBER 4 port rj45 2.5 gb +1 rj4510 + 2 PORT SFP + 10GB | E13: ITEM 9 | F13: 1 | G13: 385 | H13: =(G13*LOG_SEG) -> 7.7 | I13: =G13+H13 -> 392.7 | J13: 0.21 | K13: =I13*J13 -> 82.467 | L13: 0 | M13: =G13*L13 -> 0 | N13: =I13+M13 -> 392.7 | O13: =N13+K13 -> 475.167 | P13: =H13*F13 -> 7.7 | Q13: =N13*F13 -> 392.7 | R13: =K13*F13 -> 82.467 | S13: =M13*F13 -> 0 | T13: =Q13+S13 -> 392.7 | U13: =T13+R13 -> 475.167 | V13: =ROUND(N13/(1-MARGEN),2) -> 708.84 | W13: =X13-V13 -> 155.6 | X13: =ROUND(V13/(1-(COMI1+COMI2)),2) -> 864.44 | Y13: =Z13-X13 -> 0 | Z13: =ROUND(X13*INFLACION,2) -> 864.44 | AA13: =ROUND(Z13*J13,2) -> 181.53 | AB13: =ROUND(Z13+AA13,2) -> 1045.97 | AC13: =ROUND(AB13*BILLETE,2) -> 1490507.2 | AD13: =V13*F13 -> 708.84 | AE13: =W13*F13 -> 155.6 | AF13: =Y13*F13 -> 0 | AG13: =ROUND(Z13*F13,2) -> 864.44 | AH13: =ROUND(AA13*F13,2) -> 181.53 | AI13: =AG13+AH13 -> 1045.97 | AJ13: =AI13*BILLETE -> 1490507.2
A14: 4 | B14: UN | C14: UCM6300A | D14: GRANDSTREAM CENTRAL 250 USU 50 LLAMADAS | E14: ITEM 10 | F14: 1 | G14: 140 | H14: =(G14*LOG_SEG) -> 2.8 | I14: =G14+H14 -> 142.8 | J14: 0.105 | K14: =I14*J14 -> 14.994 | L14: 0 | M14: =G14*L14 -> 0 | N14: =I14+M14 -> 142.8 | O14: =N14+K14 -> 157.794 | P14: =H14*F14 -> 2.8 | Q14: =N14*F14 -> 142.8 | R14: =K14*F14 -> 14.994 | S14: =M14*F14 -> 0 | T14: =Q14+S14 -> 142.8 | U14: =T14+R14 -> 157.794 | V14: =ROUND(N14/(1-MARGEN),2) -> 257.76 | W14: =X14-V14 -> 56.58 | X14: =ROUND(V14/(1-(COMI1+COMI2)),2) -> 314.34 | Y14: =Z14-X14 -> 0 | Z14: =ROUND(X14*INFLACION,2) -> 314.34 | AA14: =ROUND(Z14*J14,2) -> 33.01 | AB14: =ROUND(Z14+AA14,2) -> 347.35 | AC14: =ROUND(AB14*BILLETE,2) -> 494973.75 | AD14: =V14*F14 -> 257.76 | AE14: =W14*F14 -> 56.58 | AF14: =Y14*F14 -> 0 | AG14: =ROUND(Z14*F14,2) -> 314.34 | AH14: =ROUND(AA14*F14,2) -> 33.01 | AI14: =AG14+AH14 -> 347.35 | AJ14: =AI14*BILLETE -> 494973.75
A15: 5 | B15: UN | C15: HT881 | D15: GRANDSTREAM GATEWAY 8 FXO 1 FXS 3 SIP para convertir las líneas análogas en IP | E15: ITEM 10 | F15: 1 | G15: 155 | H15: =(G15*LOG_SEG) -> 3.1 | I15: =G15+H15 -> 158.1 | J15: 0.105 | K15: =I15*J15 -> 16.6005 | L15: 0 | M15: =G15*L15 -> 0 | N15: =I15+M15 -> 158.1 | O15: =N15+K15 -> 174.7005 | P15: =H15*F15 -> 3.1 | Q15: =N15*F15 -> 158.1 | R15: =K15*F15 -> 16.6005 | S15: =M15*F15 -> 0 | T15: =Q15+S15 -> 158.1 | U15: =T15+R15 -> 174.7005 | V15: =ROUND(N15/(1-MARGEN),2) -> 285.38 | W15: =X15-V15 -> 62.64 | X15: =ROUND(V15/(1-(COMI1+COMI2)),2) -> 348.02 | Y15: =Z15-X15 -> 0 | Z15: =ROUND(X15*INFLACION,2) -> 348.02 | AA15: =ROUND(Z15*J15,2) -> 36.54 | AB15: =ROUND(Z15+AA15,2) -> 384.56 | AC15: =ROUND(AB15*BILLETE,2) -> 547998 | AD15: =V15*F15 -> 285.38 | AE15: =W15*F15 -> 62.64 | AF15: =Y15*F15 -> 0 | AG15: =ROUND(Z15*F15,2) -> 348.02 | AH15: =ROUND(AA15*F15,2) -> 36.54 | AI15: =AG15+AH15 -> 384.56 | AJ15: =AI15*BILLETE -> 547998
A16: 6 | B16: UN | C16: GRP2601P | D16: GRANDSTREAM TEL IP 2 LINEAS 2 SIP POE SIN FUENTE | E16: ITEM 11 | F16: 100 | G16: 31.15 | H16: =(G16*LOG_SEG) -> 0.623 | I16: =G16+H16 -> 31.773 | J16: 0.105 | K16: =I16*J16 -> 3.336165 | L16: 0 | M16: =G16*L16 -> 0 | N16: =I16+M16 -> 31.773 | O16: =N16+K16 -> 35.109165 | P16: =H16*F16 -> 62.3 | Q16: =N16*F16 -> 3177.3 | R16: =K16*F16 -> 333.6165 | S16: =M16*F16 -> 0 | T16: =Q16+S16 -> 3177.3 | U16: =T16+R16 -> 3510.9165 | V16: =ROUND(N16/(1-MARGEN),2) -> 57.35 | W16: =X16-V16 -> 12.59 | X16: =ROUND(V16/(1-(COMI1+COMI2)),2) -> 69.94 | Y16: =Z16-X16 -> 0 | Z16: =ROUND(X16*INFLACION,2) -> 69.94 | AA16: =ROUND(Z16*J16,2) -> 7.34 | AB16: =ROUND(Z16+AA16,2) -> 77.28 | AC16: =ROUND(AB16*BILLETE,2) -> 110124 | AD16: =V16*F16 -> 5735 | AE16: =W16*F16 -> 1259 | AF16: =Y16*F16 -> 0 | AG16: =ROUND(Z16*F16,2) -> 6994 | AH16: =ROUND(AA16*F16,2) -> 734 | AI16: =AG16+AH16 -> 7728 | AJ16: =AI16*BILLETE -> 11012400
T17: =SUM(T11:T16) -> 17957.1 | U17: =SUM(U11:U16) -> 19883.829 | AG17: =SUM(AG11:AG16) -> 39528.38 | AH17: =SUM(AH11:AH16) -> 4240.92 | AI17: =SUM(AI11:AI16) -> 43769.3 | AJ17: =SUM(AJ11:AJ16) -> 62371252
AD19: VENTA TOTAL
D20: MATERIALES | G20: COMPRA COSTOS ---- COMPRA COSTOS ----- COMPRA COSTOS---- COMPRA COSTOS COMPRA COSTOS ---- COMPRA COSTOS ----- COMPRA COSTOS---- COMPRA COSTOS | V20: PRECIO DE VENTA ----- PRECIO DE VENTA ------ PRECIO DE VENTA----- PRECIO DE VENTA---- PRECIO DE VENTA ------- PRECIO DE VENTA ----- PRECIO DE VENTA ------ PRECIO DE VENTA----- PRECIO DE VENTA---- PRECIO DE VENTA
A21: item | B21: UN | C21: CODIGO | D21: DESCRIPCIÓN | E21: PROV | F21: CANT | G21: COSTO INCIAL | H21: LOG Y SEG UNIT | I21: COSTO BASE UNIT + envío USD | J21: AlicIVA | K21: IVA | L21: % IMP INTERNO | M21: IMPUESTOS INTERNOS | N21: COSTO BASE S/IVA | O21: COSTO BASE + IVA UNIT | P21: LOG Y SEG TOTAL | Q21: COSTO BASE TOT S/ IVA | R21: IVA TOTAL | S21: IMP INTERNOS TOTAL | T21: COSTO TOT S/ IVA | U21: COSTO TOT C/ IVA + IMP | V21: NETO UNITARIO | W21: COMISIONES | X21: NETO + COMISIONES UNITARIO | Y21: COSTO FINANCIERO UNITARIO | Z21: UNIT + COSTO FINAN. (UNIT S/IVA) | AA21: IVA unitario | AB21: UNIT C/IVA usd | AC21: UNIT C/IVA pesos | AD21: NETO TOTAL | AE21: COMISIONES TOTAL | AF21: COSTO FINANCIERO TOTAL | AG21: TOTAL SIN IVA CON COSTO FINANCIERO | AH21: IVA TOTAL | AI21: TOTAL C/ IVA | AJ21: TOTAL C/IVA PESOS
A22: 1 | B22: UN | D22: Puntos de red RJ45 CAT6A (face plate dobles + 130 JACK RJ45) | E22: item 1 | F22: 130 | G22: =1.1+1 -> 2.1 | H22: =(G22*LOG_SEG) -> 0.042 | I22: =G22+H22 -> 2.142 | J22: 0.21 | K22: =I22*J22 -> 0.44982 | L22: 0 | M22: =G22*L22 -> 0 | N22: =I22+M22 -> 2.142 | O22: =N22+K22 -> 2.59182 | P22: =H22*F22 -> 5.46 | Q22: =N22*F22 -> 278.46 | R22: =K22*F22 -> 58.4766 | S22: =M22*F22 -> 0 | T22: =Q22+S22 -> 278.46 | U22: =T22+R22 -> 336.9366 | V22: =ROUND(N22/(1-MARGEN),2) -> 3.87 | W22: =X22-V22 -> 0.85 | X22: =ROUND(V22/(1-(COMI1+COMI2)),2) -> 4.72 | Y22: =Z22-X22 -> 0 | Z22: =ROUND(X22*INFLACION,2) -> 4.72 | AA22: =ROUND(Z22*J22,2) -> 0.99 | AB22: =ROUND(Z22+AA22,2) -> 5.71 | AC22: =ROUND(AB22*BILLETE,2) -> 8136.75 | AD22: =V22*F22 -> 503.1 | AE22: =W22*F22 -> 110.5 | AF22: =Y22*F22 -> 0 | AG22: =ROUND(Z22*F22,2) -> 613.6 | AH22: =ROUND(AA22*F22,2) -> 128.7 | AI22: =AG22+AH22 -> 742.3 | AJ22: =AI22*BILLETE -> 1057777.5 | AK22: =AC22*F22 -> 1057777.5
A23: 2 | B23: UN | D23: Puntos de telefonía IP (130 JACK RJ45) | E23: item2 | F23: 100 | G23: =1.1 -> 1.1 | H23: =(G23*LOG_SEG) -> 0.022 | I23: =G23+H23 -> 1.122 | J23: 0.21 | K23: =I23*J23 -> 0.23562 | L23: 0 | M23: =G23*L23 -> 0 | N23: =I23+M23 -> 1.122 | O23: =N23+K23 -> 1.35762 | P23: =H23*F23 -> 2.2 | Q23: =N23*F23 -> 112.2 | R23: =K23*F23 -> 23.562 | S23: =M23*F23 -> 0 | T23: =Q23+S23 -> 112.2 | U23: =T23+R23 -> 135.762 | V23: =ROUND(N23/(1-MARGEN),2) -> 2.03 | W23: =X23-V23 -> 0.45 | X23: =ROUND(V23/(1-(COMI1+COMI2)),2) -> 2.48 | Y23: =Z23-X23 -> 0 | Z23: =ROUND(X23*INFLACION,2) -> 2.48 | AA23: =ROUND(Z23*J23,2) -> 0.52 | AB23: =ROUND(Z23+AA23,2) -> 3 | AC23: =ROUND(AB23*BILLETE,2) -> 4275 | AD23: =V23*F23 -> 203 | AE23: =W23*F23 -> 45 | AF23: =Y23*F23 -> 0 | AG23: =ROUND(Z23*F23,2) -> 248 | AH23: =ROUND(AA23*F23,2) -> 52 | AI23: =AG23+AH23 -> 300 | AJ23: =AI23*BILLETE -> 427500 | AK23: =AC23*F23 -> 427500
A24: 3 | B24: UN | D24: Cable UTP | E24: item 3 | F24: 18 | G24: 220 | H24: =(G24*LOG_SEG) -> 4.4 | I24: =G24+H24 -> 224.4 | J24: 0.21 | K24: =I24*J24 -> 47.124 | L24: 0 | M24: =G24*L24 -> 0 | N24: =I24+M24 -> 224.4 | O24: =N24+K24 -> 271.524 | P24: =H24*F24 -> 79.2 | Q24: =N24*F24 -> 4039.2 | R24: =K24*F24 -> 848.232 | S24: =M24*F24 -> 0 | T24: =Q24+S24 -> 4039.2 | U24: =T24+R24 -> 4887.432 | V24: =ROUND(N24/(1-MARGEN),2) -> 405.05 | W24: =X24-V24 -> 88.91 | X24: =ROUND(V24/(1-(COMI1+COMI2)),2) -> 493.96 | Y24: =Z24-X24 -> 0 | Z24: =ROUND(X24*INFLACION,2) -> 493.96 | AA24: =ROUND(Z24*J24,2) -> 103.73 | AB24: =ROUND(Z24+AA24,2) -> 597.69 | AC24: =ROUND(AB24*BILLETE,2) -> 851708.25 | AD24: =V24*F24 -> 7290.9 | AE24: =W24*F24 -> 1600.38 | AF24: =Y24*F24 -> 0 | AG24: =ROUND(Z24*F24,2) -> 8891.28 | AH24: =ROUND(AA24*F24,2) -> 1867.14 | AI24: =AG24+AH24 -> 10758.42 | AJ24: =AI24*BILLETE -> 15330748 | AK24: =AC24*F24 -> 15330748
A25: 4 | B25: UN | D25: Patch panels 24 puertosCAT6A | E25: item4 | F25: 12 | G25: 55 | H25: =(G25*LOG_SEG) -> 1.1 | I25: =G25+H25 -> 56.1 | J25: 0.21 | K25: =I25*J25 -> 11.781 | L25: 0 | M25: =G25*L25 -> 0 | N25: =I25+M25 -> 56.1 | O25: =N25+K25 -> 67.881 | P25: =H25*F25 -> 13.2 | Q25: =N25*F25 -> 673.2 | R25: =K25*F25 -> 141.372 | S25: =M25*F25 -> 0 | T25: =Q25+S25 -> 673.2 | U25: =T25+R25 -> 814.572 | V25: =ROUND(N25/(1-MARGEN),2) -> 101.26 | W25: =X25-V25 -> 22.23 | X25: =ROUND(V25/(1-(COMI1+COMI2)),2) -> 123.49 | Y25: =Z25-X25 -> 0 | Z25: =ROUND(X25*INFLACION,2) -> 123.49 | AA25: =ROUND(Z25*J25,2) -> 25.93 | AB25: =ROUND(Z25+AA25,2) -> 149.42 | AC25: =ROUND(AB25*BILLETE,2) -> 212923.5 | AD25: =V25*F25 -> 1215.12 | AE25: =W25*F25 -> 266.76 | AF25: =Y25*F25 -> 0 | AG25: =ROUND(Z25*F25,2) -> 1481.88 | AH25: =ROUND(AA25*F25,2) -> 311.16 | AI25: =AG25+AH25 -> 1793.04 | AJ25: =AI25*BILLETE -> 2555082 | AK25: =AC25*F25 -> 2555082
A26: 5 | B26: UN | D26: Organizador | E26: item 5 | F26: 12 | G26: 6.75 | H26: =(G26*LOG_SEG) -> 0.135 | I26: =G26+H26 -> 6.885 | J26: 0.21 | K26: =I26*J26 -> 1.44585 | L26: 0 | M26: =G26*L26 -> 0 | N26: =I26+M26 -> 6.885 | O26: =N26+K26 -> 8.33085 | P26: =H26*F26 -> 1.62 | Q26: =N26*F26 -> 82.62 | R26: =K26*F26 -> 17.3502 | S26: =M26*F26 -> 0 | T26: =Q26+S26 -> 82.62 | U26: =T26+R26 -> 99.9702 | V26: =ROUND(N26/(1-MARGEN),2) -> 12.43 | W26: =X26-V26 -> 2.73 | X26: =ROUND(V26/(1-(COMI1+COMI2)),2) -> 15.16 | Y26: =Z26-X26 -> 0 | Z26: =ROUND(X26*INFLACION,2) -> 15.16 | AA26: =ROUND(Z26*J26,2) -> 3.18 | AB26: =ROUND(Z26+AA26,2) -> 18.34 | AC26: =ROUND(AB26*BILLETE,2) -> 26134.5 | AD26: =V26*F26 -> 149.16 | AE26: =W26*F26 -> 32.76 | AF26: =Y26*F26 -> 0 | AG26: =ROUND(Z26*F26,2) -> 181.92 | AH26: =ROUND(AA26*F26,2) -> 38.16 | AI26: =AG26+AH26 -> 220.08 | AJ26: =AI26*BILLETE -> 313614 | AK26: =AC26*F26 -> 313614
A27: 6 | B27: UN | D27: Racks metálicos 42U (Barra de tensión 10 tomas + modulo de ventilación 2 turbos) | E27: item 6 | F27: 5 | G27: =600+54+125 -> 779 | H27: =(G27*LOG_SEG) -> 15.58 | I27: =G27+H27 -> 794.58 | J27: 0.21 | K27: =I27*J27 -> 166.8618 | L27: 0 | M27: =G27*L27 -> 0 | N27: =I27+M27 -> 794.58 | O27: =N27+K27 -> 961.4418 | P27: =H27*F27 -> 77.9 | Q27: =N27*F27 -> 3972.9 | R27: =K27*F27 -> 834.309 | S27: =M27*F27 -> 0 | T27: =Q27+S27 -> 3972.9 | U27: =T27+R27 -> 4807.209 | V27: =ROUND(N27/(1-MARGEN),2) -> 1434.26 | W27: =X27-V27 -> 314.84 | X27: =ROUND(V27/(1-(COMI1+COMI2)),2) -> 1749.1 | Y27: =Z27-X27 -> 0 | Z27: =ROUND(X27*INFLACION,2) -> 1749.1 | AA27: =ROUND(Z27*J27,2) -> 367.31 | AB27: =ROUND(Z27+AA27,2) -> 2116.41 | AC27: =ROUND(AB27*BILLETE,2) -> 3015884.2 | AD27: =V27*F27 -> 7171.3 | AE27: =W27*F27 -> 1574.2 | AF27: =Y27*F27 -> 0 | AG27: =ROUND(Z27*F27,2) -> 8745.5 | AH27: =ROUND(AA27*F27,2) -> 1836.55 | AI27: =AG27+AH27 -> 10582.05 | AJ27: =AI27*BILLETE -> 15079421 | AK27: =AC27*F27 -> 15079421
A28: 7 | B28: UN | D28: UPS para racks 3KVA | E28: item 12 | F28: 5 | G28: 1700 | H28: =(G28*LOG_SEG) -> 34 | I28: =G28+H28 -> 1734 | J28: 0.21 | K28: =I28*J28 -> 364.14 | L28: 0 | M28: =G28*L28 -> 0 | N28: =I28+M28 -> 1734 | O28: =N28+K28 -> 2098.14 | P28: =H28*F28 -> 170 | Q28: =N28*F28 -> 8670 | R28: =K28*F28 -> 1820.7 | S28: =M28*F28 -> 0 | T28: =Q28+S28 -> 8670 | U28: =T28+R28 -> 10490.7 | V28: =ROUND(N28/(1-MARGEN),2) -> 3129.96 | W28: =X28-V28 -> 687.06 | X28: =ROUND(V28/(1-(COMI1+COMI2)),2) -> 3817.02 | Y28: =Z28-X28 -> 0 | Z28: =ROUND(X28*INFLACION,2) -> 3817.02 | AA28: =ROUND(Z28*J28,2) -> 801.57 | AB28: =ROUND(Z28+AA28,2) -> 4618.59 | AC28: =ROUND(AB28*BILLETE,2) -> 6581490.8 | AD28: =V28*F28 -> 15649.8 | AE28: =W28*F28 -> 3435.3 | AF28: =Y28*F28 -> 0 | AG28: =ROUND(Z28*F28,2) -> 19085.1 | AH28: =ROUND(AA28*F28,2) -> 4007.85 | AI28: =AG28+AH28 -> 23092.95 | AJ28: =AI28*BILLETE -> 32907454 | AK28: =AC28*F28 -> 32907454
A29: 8 | B29: UN | D29: Canalización (bandejas, caños) | E29: item 13 | F29: 1 | G29: =5351480/1415 -> 3781.9647 | H29: =(G29*LOG_SEG) -> 75.639293 | I29: =G29+H29 -> 3857.604 | J29: 0.21 | K29: =I29*J29 -> 810.09683 | L29: 0 | M29: =G29*L29 -> 0 | N29: =I29+M29 -> 3857.604 | O29: =N29+K29 -> 4667.7008 | P29: =H29*F29 -> 75.639293 | Q29: =N29*F29 -> 3857.604 | R29: =K29*F29 -> 810.09683 | S29: =M29*F29 -> 0 | T29: =Q29+S29 -> 3857.604 | U29: =T29+R29 -> 4667.7008 | V29: =ROUND(N29/(1-MARGEN),2) -> 6963.18 | W29: =X29-V29 -> 1528.5 | X29: =ROUND(V29/(1-(COMI1+COMI2)),2) -> 8491.68 | Y29: =Z29-X29 -> 0 | Z29: =ROUND(X29*INFLACION,2) -> 8491.68 | AA29: =ROUND(Z29*J29,2) -> 1783.25 | AB29: =ROUND(Z29+AA29,2) -> 10274.93 | AC29: =ROUND(AB29*BILLETE,2) -> 14641775 | AD29: =V29*F29 -> 6963.18 | AE29: =W29*F29 -> 1528.5 | AF29: =Y29*F29 -> 0 | AG29: =ROUND(Z29*F29,2) -> 8491.68 | AH29: =ROUND(AA29*F29,2) -> 1783.25 | AI29: =AG29+AH29 -> 10274.93 | AJ29: =AI29*BILLETE -> 14641775 | AK29: =AC29*F29 -> 14641775
A30: 9 | B30: UN | D30: Patch cords y latiguillos | E30: item 14 | F30: 230 | G30: 2.1 | H30: =(G30*LOG_SEG) -> 0.042 | I30: =G30+H30 -> 2.142 | J30: 0.21 | K30: =I30*J30 -> 0.44982 | L30: 0 | M30: =G30*L30 -> 0 | N30: =I30+M30 -> 2.142 | O30: =N30+K30 -> 2.59182 | P30: =H30*F30 -> 9.66 | Q30: =N30*F30 -> 492.66 | R30: =K30*F30 -> 103.4586 | S30: =M30*F30 -> 0 | T30: =Q30+S30 -> 492.66 | U30: =T30+R30 -> 596.1186 | V30: =ROUND(N30/(1-MARGEN),2) -> 3.87 | W30: =X30-V30 -> 0.85 | X30: =ROUND(V30/(1-(COMI1+COMI2)),2) -> 4.72 | Y30: =Z30-X30 -> 0 | Z30: =ROUND(X30*INFLACION,2) -> 4.72 | AA30: =ROUND(Z30*J30,2) -> 0.99 | AB30: =ROUND(Z30+AA30,2) -> 5.71 | AC30: =ROUND(AB30*BILLETE,2) -> 8136.75 | AD30: =V30*F30 -> 890.1 | AE30: =W30*F30 -> 195.5 | AF30: =Y30*F30 -> 0 | AG30: =ROUND(Z30*F30,2) -> 1085.6 | AH30: =ROUND(AA30*F30,2) -> 227.7 | AI30: =AG30+AH30 -> 1313.3 | AJ30: =AI30*BILLETE -> 1871452.5 | AK30: =AC30*F30 -> 1871452.5
A31: 10 | B31: UN | D31: FIBRA MM 6H EXT ANT OM3 | E31: item 15 | F31: 100 | G31: 2.15 | H31: =(G31*LOG_SEG) -> 0.043 | I31: =G31+H31 -> 2.193 | J31: 0.21 | K31: =I31*J31 -> 0.46053 | L31: 0 | M31: =G31*L31 -> 0 | N31: =I31+M31 -> 2.193 | O31: =N31+K31 -> 2.65353 | P31: =H31*F31 -> 4.3 | Q31: =N31*F31 -> 219.3 | R31: =K31*F31 -> 46.053 | S31: =M31*F31 -> 0 | T31: =Q31+S31 -> 219.3 | U31: =T31+R31 -> 265.353 | V31: =ROUND(N31/(1-MARGEN),2) -> 3.96 | W31: =X31-V31 -> 0.87 | X31: =ROUND(V31/(1-(COMI1+COMI2)),2) -> 4.83 | Y31: =Z31-X31 -> 0 | Z31: =ROUND(X31*INFLACION,2) -> 4.83 | AA31: =ROUND(Z31*J31,2) -> 1.01 | AB31: =ROUND(Z31+AA31,2) -> 5.84 | AC31: =ROUND(AB31*BILLETE,2) -> 8322 | AD31: =V31*F31 -> 396 | AE31: =W31*F31 -> 87 | AF31: =Y31*F31 -> 0 | AG31: =ROUND(Z31*F31,2) -> 483 | AH31: =ROUND(AA31*F31,2) -> 101 | AI31: =AG31+AH31 -> 584 | AJ31: =AI31*BILLETE -> 832200 | AK31: =AC31*F31 -> 832200
A32: 11 | B32: UN | D32: Patch Panel de Fibra Óptica (FCP) | E32: item 16 | F32: 5 | G32: =70000/1415 -> 49.469965 | H32: =(G32*LOG_SEG) -> 0.98939929 | I32: =G32+H32 -> 50.459364 | J32: 0.21 | K32: =I32*J32 -> 10.596466 | L32: 0 | M32: =G32*L32 -> 0 | N32: =I32+M32 -> 50.459364 | O32: =N32+K32 -> 61.05583 | P32: =H32*F32 -> 4.9469965 | Q32: =N32*F32 -> 252.29682 | R32: =K32*F32 -> 52.982332 | S32: =M32*F32 -> 0 | T32: =Q32+S32 -> 252.29682 | U32: =T32+R32 -> 305.27915 | V32: =ROUND(N32/(1-MARGEN),2) -> 91.08 | W32: =X32-V32 -> 19.99 | X32: =ROUND(V32/(1-(COMI1+COMI2)),2) -> 111.07 | Y32: =Z32-X32 -> 0 | Z32: =ROUND(X32*INFLACION,2) -> 111.07 | AA32: =ROUND(Z32*J32,2) -> 23.32 | AB32: =ROUND(Z32+AA32,2) -> 134.39 | AC32: =ROUND(AB32*BILLETE,2) -> 191505.75 | AD32: =V32*F32 -> 455.4 | AE32: =W32*F32 -> 99.95 | AF32: =Y32*F32 -> 0 | AG32: =ROUND(Z32*F32,2) -> 555.35 | AH32: =ROUND(AA32*F32,2) -> 116.6 | AI32: =AG32+AH32 -> 671.95 | AJ32: =AI32*BILLETE -> 957528.75 | AK32: =AC32*F32 -> 957528.75
A33: 12 | B33: UN | D33: BANDEJA DE FO DESL | E33: item 17 | F33: 5 | G33: 50 | H33: =(G33*LOG_SEG) -> 1 | I33: =G33+H33 -> 51 | J33: 0.21 | K33: =I33*J33 -> 10.71 | L33: 0 | M33: =G33*L33 -> 0 | N33: =I33+M33 -> 51 | O33: =N33+K33 -> 61.71 | P33: =H33*F33 -> 5 | Q33: =N33*F33 -> 255 | R33: =K33*F33 -> 53.55 | S33: =M33*F33 -> 0 | T33: =Q33+S33 -> 255 | U33: =T33+R33 -> 308.55 | V33: =ROUND(N33/(1-MARGEN),2) -> 92.06 | W33: =X33-V33 -> 20.21 | X33: =ROUND(V33/(1-(COMI1+COMI2)),2) -> 112.27 | Y33: =Z33-X33 -> 0 | Z33: =ROUND(X33*INFLACION,2) -> 112.27 | AA33: =ROUND(Z33*J33,2) -> 23.58 | AB33: =ROUND(Z33+AA33,2) -> 135.85 | AC33: =ROUND(AB33*BILLETE,2) -> 193586.25 | AD33: =V33*F33 -> 460.3 | AE33: =W33*F33 -> 101.05 | AF33: =Y33*F33 -> 0 | AG33: =ROUND(Z33*F33,2) -> 561.35 | AH33: =ROUND(AA33*F33,2) -> 117.9 | AI33: =AG33+AH33 -> 679.25 | AJ33: =AI33*BILLETE -> 967931.25 | AK33: =AC33*F33 -> 967931.25
A34: 13 | B34: UN | D34: CUPLER DUPLEX LC OM3 | E34: item 18 | F34: 30 | G34: 2.5 | H34: =(G34*LOG_SEG) -> 0.05 | I34: =G34+H34 -> 2.55 | J34: 0.21 | K34: =I34*J34 -> 0.5355 | L34: 0 | M34: =G34*L34 -> 0 | N34: =I34+M34 -> 2.55 | O34: =N34+K34 -> 3.0855 | P34: =H34*F34 -> 1.5 | Q34: =N34*F34 -> 76.5 | R34: =K34*F34 -> 16.065 | S34: =M34*F34 -> 0 | T34: =Q34+S34 -> 76.5 | U34: =T34+R34 -> 92.565 | V34: =ROUND(N34/(1-MARGEN),2) -> 4.6 | W34: =X34-V34 -> 1.01 | X34: =ROUND(V34/(1-(COMI1+COMI2)),2) -> 5.61 | Y34: =Z34-X34 -> 0 | Z34: =ROUND(X34*INFLACION,2) -> 5.61 | AA34: =ROUND(Z34*J34,2) -> 1.18 | AB34: =ROUND(Z34+AA34,2) -> 6.79 | AC34: =ROUND(AB34*BILLETE,2) -> 9675.75 | AD34: =V34*F34 -> 138 | AE34: =W34*F34 -> 30.3 | AF34: =Y34*F34 -> 0 | AG34: =ROUND(Z34*F34,2) -> 168.3 | AH34: =ROUND(AA34*F34,2) -> 35.4 | AI34: =AG34+AH34 -> 203.7 | AJ34: =AI34*BILLETE -> 290272.5 | AK34: =AC34*F34 -> 290272.5
A35: 14 | B35: UN | D35: PIGTAIL FO LC OM3 1,5 MTS | E35: item 19 | F35: 60 | G35: 2.75 | H35: =(G35*LOG_SEG) -> 0.055 | I35: =G35+H35 -> 2.805 | J35: 0.21 | K35: =I35*J35 -> 0.58905 | L35: 0 | M35: =G35*L35 -> 0 | N35: =I35+M35 -> 2.805 | O35: =N35+K35 -> 3.39405 | P35: =H35*F35 -> 3.3 | Q35: =N35*F35 -> 168.3 | R35: =K35*F35 -> 35.343 | S35: =M35*F35 -> 0 | T35: =Q35+S35 -> 168.3 | U35: =T35+R35 -> 203.643 | V35: =ROUND(N35/(1-MARGEN),2) -> 5.06 | W35: =X35-V35 -> 1.11 | X35: =ROUND(V35/(1-(COMI1+COMI2)),2) -> 6.17 | Y35: =Z35-X35 -> 0 | Z35: =ROUND(X35*INFLACION,2) -> 6.17 | AA35: =ROUND(Z35*J35,2) -> 1.3 | AB35: =ROUND(Z35+AA35,2) -> 7.47 | AC35: =ROUND(AB35*BILLETE,2) -> 10644.75 | AD35: =V35*F35 -> 303.6 | AE35: =W35*F35 -> 66.6 | AF35: =Y35*F35 -> 0 | AG35: =ROUND(Z35*F35,2) -> 370.2 | AH35: =ROUND(AA35*F35,2) -> 78 | AI35: =AG35+AH35 -> 448.2 | AJ35: =AI35*BILLETE -> 638685 | AK35: =AC35*F35 -> 638685
A36: 15 | B36: UN | D36: PATCH CORD FO LC DUPLEX 2 MTS OM3 | E36: item 20 | F36: 12 | G36: 9 | H36: =(G36*LOG_SEG) -> 0.18 | I36: =G36+H36 -> 9.18 | J36: 0.21 | K36: =I36*J36 -> 1.9278 | L36: 0 | M36: =G36*L36 -> 0 | N36: =I36+M36 -> 9.18 | O36: =N36+K36 -> 11.1078 | P36: =H36*F36 -> 2.16 | Q36: =N36*F36 -> 110.16 | R36: =K36*F36 -> 23.1336 | S36: =M36*F36 -> 0 | T36: =Q36+S36 -> 110.16 | U36: =T36+R36 -> 133.2936 | V36: =ROUND(N36/(1-MARGEN),2) -> 16.57 | W36: =X36-V36 -> 3.64 | X36: =ROUND(V36/(1-(COMI1+COMI2)),2) -> 20.21 | Y36: =Z36-X36 -> 0 | Z36: =ROUND(X36*INFLACION,2) -> 20.21 | AA36: =ROUND(Z36*J36,2) -> 4.24 | AB36: =ROUND(Z36+AA36,2) -> 24.45 | AC36: =ROUND(AB36*BILLETE,2) -> 34841.25 | AD36: =V36*F36 -> 198.84 | AE36: =W36*F36 -> 43.68 | AF36: =Y36*F36 -> 0 | AG36: =ROUND(Z36*F36,2) -> 242.52 | AH36: =ROUND(AA36*F36,2) -> 50.88 | AI36: =AG36+AH36 -> 293.4 | AJ36: =AI36*BILLETE -> 418095 | AK36: =AC36*F36 -> 418095
A37: 16 | B37: UN | D37: Transceiver Óptico SFP 1OGb | E37: item 21 | F37: 20 | G37: =50000/1415 -> 35.335689 | H37: =(G37*LOG_SEG) -> 0.70671378 | I37: =G37+H37 -> 36.042403 | J37: 0.21 | K37: =I37*J37 -> 7.5689046 | L37: 0 | M37: =G37*L37 -> 0 | N37: =I37+M37 -> 36.042403 | O37: =N37+K37 -> 43.611307 | P37: =H37*F37 -> 14.134276 | Q37: =N37*F37 -> 720.84806 | R37: =K37*F37 -> 151.37809 | S37: =M37*F37 -> 0 | T37: =Q37+S37 -> 720.84806 | U37: =T37+R37 -> 872.22615 | V37: =ROUND(N37/(1-MARGEN),2) -> 65.06 | W37: =X37-V37 -> 14.28 | X37: =ROUND(V37/(1-(COMI1+COMI2)),2) -> 79.34 | Y37: =Z37-X37 -> 0 | Z37: =ROUND(X37*INFLACION,2) -> 79.34 | AA37: =ROUND(Z37*J37,2) -> 16.66 | AB37: =ROUND(Z37+AA37,2) -> 96 | AC37: =ROUND(AB37*BILLETE,2) -> 136800 | AD37: =V37*F37 -> 1301.2 | AE37: =W37*F37 -> 285.6 | AF37: =Y37*F37 -> 0 | AG37: =ROUND(Z37*F37,2) -> 1586.8 | AH37: =ROUND(AA37*F37,2) -> 333.2 | AI37: =AG37+AH37 -> 1920 | AJ37: =AI37*BILLETE -> 2736000 | AK37: =AC37*F37 -> 2736000
T38: =SUM(T22:T37) -> 23981.249 | U38: =SUM(U22:U37) -> 29017.311 | AG38: =SUM(AG22:AG37) -> 52792.08 | AH38: =SUM(AH22:AH37) -> 11085.49 | AI38: =SUM(AI22:AI37) -> 63877.57 | AJ38: =SUM(AJ22:AJ37) -> 91025537 | AK38: =SUM(AK22:AK37) -> 91025537
T41: =T6+T17+T38 -> 77638.349 | U41: =U6+U17+U38 -> 92098.14 | AG41: =AG6+AG17+AG38 -> 170906.35 | AH41: =AH6+AH17+AH38 -> 31829.44 | AI41: =AI6+AI17+AI38 -> 202735.79 | AJ41: =AJ6+AJ17+AJ38 -> 2.888985e+08
AG42: =AG41*1425 -> 2.4354155e+08 | AH42: =AH41*1425 -> 45356952 | AI42: =AJ41/1415 -> 204168.55 | AJ42: =AG42+AH42 -> 2.888985e+08
AH44: JUSTIPRECIO | AI44: 205000 | AJ44: =AI44*1415 -> 290075000
AH45: POLIZA 10% ARRIBA JUSTI | AI45: =AI44*1.1 -> 225500 | AJ45: =AI45*1425 -> 3.213375e+08
...

Sheet Estr Costos
B1: SBD
H3: Costos Generales | M3: Impuestos Generales
H4: Costos Directos | I4: Costos Indirectos | K4: TOTAL COST. GEN | M4: Impuestos 1 | O4: Impuestos 2 Fa Total | R4: TOTAL IMP.GEN
A5: Renglón | B5: Unidad | D5: Descripción | E5: Precio Unitario S/ IVA | F5: Precio Unit ($) C/IVA | G5: FA BASE | H5: Equipos/Recursos | I5: Logistica y seguros | J5: Gtos financieros | K5: TOTAL ($) | L5: Incidencia | M5: Imp. Gan.35% | N5: IVA 21% | O5: IVA 21% | P5: Ingr. Brutos 5% | Q5: Imp. Trcia. 1,2% | R5: TOTAL ($) | S5: Incidencia | T5: Utilidad Neta | U5: % Ut. Neta
C6: 1.1 | D6: Puntos de red RJ45 CAT6A | E6: =F6-O6 -> #REF! | F6: =#REF! -> #REF! | G6: =E6-P6 -> #REF! | H6: =G6*60% -> #REF! | I6: =G6*3% -> #REF! | J6: =G6*5% -> #REF! | K6: =SUM(H6:J6) -> #REF! | L6: =K6/F6 -> #REF! | M6: =(G6-K6-Q6)*35% -> #REF! | N6: ='Prof&LosT'!J22 -> 0.21 | O6: =F6*N6 -> #REF! | P6: =E6*5% -> #REF! | Q6: =F6*1.2% -> #REF! | R6: =SUM(M6:Q6) -> #REF! | S6: =R6/F6 -> #REF! | T6: =F6-K6-R6 -> #REF! | U6: =T6/F6 -> #REF!
C7: 1.2 | D7: Puntos de telefonía IP | E7: =F7-O7 -> #REF! | F7: =#REF! -> #REF! | G7: =E7-P7 -> #REF! | H7: =G7*60% -> #REF! | I7: =G7*3% -> #REF! | J7: =G7*5% -> #REF! | K7: =SUM(H7:J7) -> #REF! | L7: =K7/F7 -> #REF! | M7: =(G7-K7-Q7)*35% -> #REF! | N7: ='Prof&LosT'!J23 -> 0.21 | O7: =F7*N7 -> #REF! | P7: =E7*5% -> #REF! | Q7: =F7*1.2% -> #REF! | R7: =SUM(M7:Q7) -> #REF! | S7: =R7/F7 -> #REF! | T7: =F7-K7-R7 -> #REF! | U7: =T7/F7 -> #REF!
C8: 1.3 | D8: Cable UTP | E8: =F8-O8 -> #REF! | F8: =#REF! -> #REF! | G8: =E8-P8 -> #REF! | H8: =G8*60% -> #REF! | I8: =G8*3% -> #REF! | J8: =G8*5% -> #REF! | K8: =SUM(H8:J8) -> #REF! | L8: =K8/F8 -> #REF! | M8: =(G8-K8-Q8)*35% -> #REF! | N8: ='Prof&LosT'!J24 -> 0.21 | O8: =F8*N8 -> #REF! | P8: =E8*5% -> #REF! | Q8: =F8*1.2% -> #REF! | R8: =SUM(M8:Q8) -> #REF! | S8: =R8/F8 -> #REF! | T8: =F8-K8-R8 -> #REF! | U8: =T8/F8 -> #REF!
C9: 1.4 | D9: Patch panels 24 puertos CAT6A | E9: =F9-O9 -> #REF! | F9: =#REF! -> #REF! | G9: =E9-P9 -> #REF! | H9: =G9*60% -> #REF! | I9: =G9*3% -> #REF! | J9: =G9*5% -> #REF! | K9: =SUM(H9:J9) -> #REF! | L9: =K9/F9 -> #REF! | M9: =(G9-K9-Q9)*35% -> #REF! | N9: ='Prof&LosT'!J25 -> 0.21 | O9: =F9*N9 -> #REF! | P9: =E9*5% -> #REF! | Q9: =F9*1.2% -> #REF! | R9: =SUM(M9:Q9) -> #REF! | S9: =R9/F9 -> #REF! | T9: =F9-K9-R9 -> #REF! | U9: =T9/F9 -> #REF!
C10: 1.5 | D10: Organizador | E10: =F10-O10 -> #REF! | F10: =#REF! -> #REF! | G10: =E10-P10 -> #REF! | H10: =G10*60% -> #REF! | I10: =G10*3% -> #REF! | J10: =G10*5% -> #REF! | K10: =SUM(H10:J10) -> #REF! | L10: =K10/F10 -> #REF! | M10: =(G10-K10-Q10)*35% -> #REF! | N10: ='Prof&LosT'!J26 -> 0.21 | O10: =F10*N10 -> #REF! | P10: =E10*5% -> #REF! | Q10: =F10*1.2% -> #REF! | R10: =SUM(M10:Q10) -> #REF! | S10: =R10/F10 -> #REF! | T10: =F10-K10-R10 -> #REF! | U10: =T10/F10 -> #REF!
C11: 1.6 | D11: Racks metálicos 42U | E11: =F11-O11 -> #REF! | F11: =#REF! -> #REF! | G11: =E11-P11 -> #REF! | H11: =G11*60% -> #REF! | I11: =G11*3% -> #REF! | J11: =G11*5% -> #REF! | K11: =SUM(H11:J11) -> #REF! | L11: =K11/F11 -> #REF! | M11: =(G11-K11-Q11)*35% -> #REF! | N11: ='Prof&LosT'!J27 -> 0.21 | O11: =F11*N11 -> #REF! | P11: =E11*5% -> #REF! | Q11: =F11*1.2% -> #REF! | R11: =SUM(M11:Q11) -> #REF! | S11: =R11/F11 -> #REF! | T11: =F11-K11-R11 -> #REF! | U11: =T11/F11 -> #REF!
C12: 1.7 | D12: Switches administrables 48 port | E12: =F12-O12 -> #REF! | F12: =#REF! -> #REF! | G12: =E12-P12 -> #REF! | H12: =G12*60% -> #REF! | I12: =G12*3% -> #REF! | J12: =G12*5% -> #REF! | K12: =SUM(H12:J12) -> #REF! | L12: =K12/F12 -> #REF! | M12: =(G12-K12-Q12)*35% -> #REF! | N12: ='Prof&LosT'!J11 -> 0.105 | O12: =F12*N12 -> #REF! | P12: =E12*5% -> #REF! | Q12: =F12*1.2% -> #REF! | R12: =SUM(M12:Q12) -> #REF! | S12: =R12/F12 -> #REF! | T12: =F12-K12-R12 -> #REF! | U12: =T12/F12 -> #REF!
C13: 1.8 | D13: Access Points Wi-Fi 6 | E13: =F13-O13 -> #REF! | F13: =#REF! -> #REF! | G13: =E13-P13 -> #REF! | H13: =G13*60% -> #REF! | I13: =G13*3% -> #REF! | J13: =G13*5% -> #REF! | K13: =SUM(H13:J13) -> #REF! | L13: =K13/F13 -> #REF! | M13: =(G13-K13-Q13)*35% -> #REF! | N13: ='Prof&LosT'!J12 -> 0.105 | O13: =F13*N13 -> #REF! | P13: =E13*5% -> #REF! | Q13: =F13*1.2% -> #REF! | R13: =SUM(M13:Q13) -> #REF! | S13: =R13/F13 -> #REF! | T13: =F13-K13-R13 -> #REF! | U13: =T13/F13 -> #REF!
C14: 1.9 | D14: Controladora Wi-Fi | E14: =F14-O14 -> #REF! | F14: =#REF! -> #REF! | G14: =E14-P14 -> #REF! | H14: =G14*60% -> #REF! | I14: =G14*3% -> #REF! | J14: =G14*5% -> #REF! | K14: =SUM(H14:J14) -> #REF! | L14: =K14/F14 -> #REF! | M14: =(G14-K14-Q14)*35% -> #REF! | N14: ='Prof&LosT'!J13 -> 0.21 | O14: =F14*N14 -> #REF! | P14: =E14*5% -> #REF! | Q14: =F14*1.2% -> #REF! | R14: =SUM(M14:Q14) -> #REF! | S14: =R14/F14 -> #REF! | T14: =F14-K14-R14 -> #REF! | U14: =T14/F14 -> #REF!
C15: 1.10 | D15: PBX IP (central telefónica) incluye equipos GRANDSTREAM GATEWAY 8 FXO 1 FXS 3 SIP para convertir las líneas análogas en IP | E15: =F15-O15 -> #REF! | F15: =#REF! -> #REF! | G15: =E15-P15 -> #REF! | H15: =G15*60% -> #REF! | I15: =G15*3% -> #REF! | J15: =G15*5% -> #REF! | K15: =SUM(H15:J15) -> #REF! | L15: =K15/F15 -> #REF! | M15: =(G15-K15-Q15)*35% -> #REF! | N15: ='Prof&LosT'!J14 -> 0.105 | O15: =F15*N15 -> #REF! | P15: =E15*5% -> #REF! | Q15: =F15*1.2% -> #REF! | R15: =SUM(M15:Q15) -> #REF! | S15: =R15/F15 -> #REF! | T15: =F15-K15-R15 -> #REF! | U15: =T15/F15 -> #REF!
C16: 1.11 | D16: Teléfonos IP administrativos | E16: =F16-O16 -> #REF! | F16: =#REF! -> #REF! | G16: =E16-P16 -> #REF! | H16: =G16*60% -> #REF! | I16: =G16*3% -> #REF! | J16: =G16*5% -> #REF! | K16: =SUM(H16:J16) -> #REF! | L16: =K16/F16 -> #REF! | M16: =(G16-K16-Q16)*35% -> #REF! | N16: ='Prof&LosT'!J15 -> 0.105 | O16: =F16*N16 -> #REF! | P16: =E16*5% -> #REF! | Q16: =F16*1.2% -> #REF! | R16: =SUM(M16:Q16) -> #REF! | S16: =R16/F16 -> #REF! | T16: =F16-K16-R16 -> #REF! | U16: =T16/F16 -> #REF!
C17: 1.12 | D17: UPS para racks | E17: =F17-O17 -> #REF! | F17: =#REF! -> #REF! | G17: =E17-P17 -> #REF! | H17: =G17*60% -> #REF! | I17: =G17*3% -> #REF! | J17: =G17*5% -> #REF! | K17: =SUM(H17:J17) -> #REF! | L17: =K17/F17 -> #REF! | M17: =(G17-K17-Q17)*35% -> #REF! | N17: ='Prof&LosT'!J28 -> 0.21 | O17: =F17*N17 -> #REF! | P17: =E17*5% -> #REF! | Q17: =F17*1.2% -> #REF! | R17: =SUM(M17:Q17) -> #REF! | S17: =R17/F17 -> #REF! | T17: =F17-K17-R17 -> #REF! | U17: =T17/F17 -> #REF!
C18: 1.13 | D18: Canalización (bandejas, caños) | E18: =F18-O18 -> #REF! | F18: =#REF! -> #REF! | G18: =E18-P18 -> #REF! | H18: =G18*60% -> #REF! | I18: =G18*3% -> #REF! | J18: =G18*5% -> #REF! | K18: =SUM(H18:J18) -> #REF! | L18: =K18/F18 -> #REF! | M18: =(G18-K18-Q18)*35% -> #REF! | N18: ='Prof&LosT'!J29 -> 0.21 | O18: =F18*N18 -> #REF! | P18: =E18*5% -> #REF! | Q18: =F18*1.2% -> #REF! | R18: =SUM(M18:Q18) -> #REF! | S18: =R18/F18 -> #REF! | T18: =F18-K18-R18 -> #REF! | U18: =T18/F18 -> #REF!
C19: 1.14 | D19: Patch cords y latiguillos | E19: =F19-O19 -> #REF! | F19: =#REF! -> #REF! | G19: =E19-P19 -> #REF! | H19: =G19*60% -> #REF! | I19: =G19*3% -> #REF! | J19: =G19*5% -> #REF! | K19: =SUM(H19:J19) -> #REF! | L19: =K19/F19 -> #REF! | M19: =(G19-K19-Q19)*35% -> #REF! | N19: ='Prof&LosT'!J30 -> 0.21 | O19: =F19*N19 -> #REF! | P19: =E19*5% -> #REF! | Q19: =F19*1.2% -> #REF! | R19: =SUM(M19:Q19) -> #REF! | S19: =R19/F19 -> #REF! | T19: =F19-K19-R19 -> #REF! | U19: =T19/F19 -> #REF!
C20: 1.15 | D20: Instalación y puesta en punto | E20: =F20-O20 -> #REF! | F20: =#REF! -> #REF! | G20: =E20-P20 -> #REF! | H20: =G20*60% -> #REF! | I20: =G20*3% -> #REF! | J20: =G20*5% -> #REF! | K20: =SUM(H20:J20) -> #REF! | L20: =K20/F20 -> #REF! | M20: =(G20-K20-Q20)*35% -> #REF! | N20: ='Prof&LosT'!J31 -> 0.21 | O20: =F20*N20 -> #REF! | P20: =E20*5% -> #REF! | Q20: =F20*1.2% -> #REF! | R20: =SUM(M20:Q20) -> #REF! | S20: =R20/F20 -> #REF! | T20: =F20-K20-R20 -> #REF! | U20: =T20/F20 -> #REF!
C21: 1.16 | D21: Materiales FO | E21: =F21-O21 -> #REF! | F21: =#REF! -> #REF! | G21: =E21-P21 -> #REF! | H21: =G21*60% -> #REF! | I21: =G21*3% -> #REF! | J21: =G21*5% -> #REF! | K21: =SUM(H21:J21) -> #REF! | L21: =K21/F21 -> #REF! | M21: =(G21-K21-Q21)*35% -> #REF! | N21: 0.21 | O21: =F21*N21 -> #REF! | P21: =E21*5% -> #REF! | Q21: =F21*1.2% -> #REF! | R21: =SUM(M21:Q21) -> #REF! | S21: =R21/F21 -> #REF! | T21: =F21-K21-R21 -> #REF! | U21: =T21/F21 -> #REF!

Sheet INDICES
B1: CAMBIO DE DIVISAS
A2: FECHA | B2: DESCRIPCIÓN | C2: VALOR
B3: MARGEN | C3: 0.446
A4: 45595 | B4: DÓLAR BILLETE BNA VENTA | C4: 1425
B11: INDICE DE INFLACION
C12: ANUAL
B13: INDICE DE INFLACION
B14: INDICE MENSUALIZADO
B15: CANTIDAD DE MESES
B16: INDICE ACUMULADO INFLACIÓN | C16: =(1+C14)^C15 -> 1
B19: COMISIONES
B20: COMISION VENTA | C20: 0.03
B21: COMISION ORGANISMO | C21: 0.15
B23: INDICE ASOCIADOS A COSTOS
B24: LOGISTICA + SEGUROS | C24: 0.02

Sheet LISTA ORGANISMO

Sheet MATERIALES 

Sheet MO
